Traceback (most recent call last):
  File "/opt/anaconda3/envs/book_env/lib/python3.10/site-packages/jupyter_cache/executors/utils.py", line 58, in single_nb_execution
    executenb(
  File "/opt/anaconda3/envs/book_env/lib/python3.10/site-packages/nbclient/client.py", line 1204, in execute
    return NotebookClient(nb=nb, resources=resources, km=km, **kwargs).execute()
  File "/opt/anaconda3/envs/book_env/lib/python3.10/site-packages/nbclient/util.py", line 84, in wrapped
    return just_run(coro(*args, **kwargs))
  File "/opt/anaconda3/envs/book_env/lib/python3.10/site-packages/nbclient/util.py", line 62, in just_run
    return loop.run_until_complete(coro)
  File "/opt/anaconda3/envs/book_env/lib/python3.10/asyncio/base_events.py", line 649, in run_until_complete
    return future.result()
  File "/opt/anaconda3/envs/book_env/lib/python3.10/site-packages/nbclient/client.py", line 663, in async_execute
    await self.async_execute_cell(
  File "/opt/anaconda3/envs/book_env/lib/python3.10/site-packages/nbclient/client.py", line 965, in async_execute_cell
    await self._check_raise_for_error(cell, cell_index, exec_reply)
  File "/opt/anaconda3/envs/book_env/lib/python3.10/site-packages/nbclient/client.py", line 862, in _check_raise_for_error
    raise CellExecutionError.from_cell_and_msg(cell, exec_reply_content)
nbclient.exceptions.CellExecutionError: An error occurred while executing the following cell:
------------------
import numpy as np
import matplotlib.pyplot as plt

x_hat = np.array([1, 0, 0])
y_hat = np.array([0, 1, 0])
z_hat = np.array([0, 0, 1])

fig = plt.figure()
ax = fig.add_subplot(111, projection='3d')

scale_factor = 1

ax.quiver(0, 0, 0, *x_hat, color='r', label='$\\hat{x}$', length=scale_factor, arrow_length_ratio=0.1)
ax.quiver(0, 0, 0, *y_hat, color='g', label='$\\hat{y}$', length=scale_factor, arrow_length_ratio=0.1)
ax.quiver(0, 0, 0, *z_hat, color='b', label='$\\hat{z}$', length=scale_factor, arrow_length_ratio=0.1)

ax.set_xlim([-1.5, 1.5])
ax.set_ylim([-1.5, 1.5])
ax.set_zlim([-1.5, 1.5])
ax.set_xlabel('X')
ax.set_ylabel('Y')
ax.set_zlabel('Z')

ax.view_init(azim=45)
ax.legend()
ax.set_aspect("equal")
ax.set_title("Unit Vectors in 3D Space")
fig.tight_layout()
plt.show()

------------------

[0;31m---------------------------------------------------------------------------[0m
[0;31mNotImplementedError[0m                       Traceback (most recent call last)
Cell [0;32mIn[10], line 26[0m
[1;32m     24[0m ax[38;5;241m.[39mview_init(azim[38;5;241m=[39m[38;5;241m45[39m)
[1;32m     25[0m ax[38;5;241m.[39mlegend()
[0;32m---> 26[0m [43max[49m[38;5;241;43m.[39;49m[43mset_aspect[49m[43m([49m[38;5;124;43m"[39;49m[38;5;124;43mequal[39;49m[38;5;124;43m"[39;49m[43m)[49m
[1;32m     27[0m ax[38;5;241m.[39mset_title([38;5;124m"[39m[38;5;124mUnit Vectors in 3D Space[39m[38;5;124m"[39m)
[1;32m     28[0m fig[38;5;241m.[39mtight_layout()

File [0;32m/opt/anaconda3/envs/book_env/lib/python3.10/site-packages/mpl_toolkits/mplot3d/axes3d.py:311[0m, in [0;36mAxes3D.set_aspect[0;34m(self, aspect, adjustable, anchor, share)[0m
[1;32m    258[0m [38;5;250m[39m[38;5;124;03m"""[39;00m
[1;32m    259[0m [38;5;124;03mSet the aspect ratios.[39;00m
[1;32m    260[0m 
[0;32m   (...)[0m
[1;32m    308[0m [38;5;124;03mmpl_toolkits.mplot3d.axes3d.Axes3D.set_box_aspect[39;00m
[1;32m    309[0m [38;5;124;03m"""[39;00m
[1;32m    310[0m [38;5;28;01mif[39;00m aspect [38;5;241m!=[39m [38;5;124m'[39m[38;5;124mauto[39m[38;5;124m'[39m:
[0;32m--> 311[0m     [38;5;28;01mraise[39;00m [38;5;167;01mNotImplementedError[39;00m(
[1;32m    312[0m         [38;5;124m"[39m[38;5;124mAxes3D currently only supports the aspect argument [39m[38;5;124m"[39m
[1;32m    313[0m         [38;5;124mf[39m[38;5;124m"[39m[38;5;124m'[39m[38;5;124mauto[39m[38;5;124m'[39m[38;5;124m. You passed in [39m[38;5;132;01m{[39;00maspect[38;5;132;01m!r}[39;00m[38;5;124m.[39m[38;5;124m"[39m
[1;32m    314[0m     )
[1;32m    315[0m [38;5;28msuper[39m()[38;5;241m.[39mset_aspect(
[1;32m    316[0m     aspect, adjustable[38;5;241m=[39madjustable, anchor[38;5;241m=[39manchor, share[38;5;241m=[39mshare)

[0;31mNotImplementedError[0m: Axes3D currently only supports the aspect argument 'auto'. You passed in 'equal'.
NotImplementedError: Axes3D currently only supports the aspect argument 'auto'. You passed in 'equal'.

